<?xml version="1.0" encoding="UTF-8"?>
<testng-results ignored="0" total="6" passed="1" failed="5" skipped="0">
  <reporter-output>
  </reporter-output>
  <suite started-at="2023-05-31T15:37:19 IST" name="Default suite" finished-at="2023-05-31T15:38:12 IST" duration-ms="52713">
    <groups>
    </groups>
    <test started-at="2023-05-31T15:37:19 IST" name="Default test" finished-at="2023-05-31T15:38:12 IST" duration-ms="52713">
      <class name="testcases.TC001_DDTLoginTest">
        <test-method is-config="true" signature="startBrow()[pri:0, instance:testcases.TC001_DDTLoginTest@3ee37e5a]" started-at="2023-05-31T15:37:19 IST" name="startBrow" finished-at="2023-05-31T15:37:36 IST" duration-ms="16658" status="PASS">
          <reporter-output>
          </reporter-output>
        </test-method> <!-- startBrow -->
        <test-method signature="DDT_LoginTestTC001(java.lang.String,java.lang.String)[pri:0, instance:testcases.TC001_DDTLoginTest@3ee37e5a]" started-at="2023-05-31T15:37:40 IST" name="DDT_LoginTestTC001" data-provider="DDTExcel" finished-at="2023-05-31T15:37:46 IST" duration-ms="6346" status="PASS">
          <params>
            <param index="0">
              <value>
                <![CDATA[mngr504995]]>
              </value>
            </param>
            <param index="1">
              <value>
                <![CDATA[EtUsYrY]]>
              </value>
            </param>
          </params>
          <reporter-output>
          </reporter-output>
        </test-method> <!-- DDT_LoginTestTC001 -->
        <test-method signature="DDT_LoginTestTC001(java.lang.String,java.lang.String)[pri:0, instance:testcases.TC001_DDTLoginTest@3ee37e5a]" started-at="2023-05-31T15:37:46 IST" name="DDT_LoginTestTC001" data-provider="DDTExcel" finished-at="2023-05-31T15:37:50 IST" duration-ms="3545" status="FAIL">
          <params>
            <param index="0">
              <value>
                <![CDATA[Hadi]]>
              </value>
            </param>
            <param index="1">
              <value>
                <![CDATA[Heena]]>
              </value>
            </param>
          </params>
          <exception class="java.lang.AssertionError">
            <full-stacktrace>
              <![CDATA[java.lang.AssertionError
at org.junit.Assert.fail(Assert.java:86)
at org.junit.Assert.assertTrue(Assert.java:41)
at org.junit.Assert.assertTrue(Assert.java:52)
at testcases.TC001_DDTLoginTest.DDT_LoginTestTC001(TC001_DDTLoginTest.java:28)
at java.base/jdk.internal.reflect.NativeMethodAccessorImpl.invoke0(Native Method)
at java.base/jdk.internal.reflect.NativeMethodAccessorImpl.invoke(NativeMethodAccessorImpl.java:64)
at java.base/jdk.internal.reflect.DelegatingMethodAccessorImpl.invoke(DelegatingMethodAccessorImpl.java:43)
at java.base/java.lang.reflect.Method.invoke(Method.java:564)
at org.testng.internal.MethodInvocationHelper.invokeMethod(MethodInvocationHelper.java:133)
at org.testng.internal.TestInvoker.invokeMethod(TestInvoker.java:598)
at org.testng.internal.TestInvoker.invokeTestMethod(TestInvoker.java:173)
at org.testng.internal.MethodRunner.runInSequence(MethodRunner.java:46)
at org.testng.internal.TestInvoker$MethodInvocationAgent.invoke(TestInvoker.java:824)
at org.testng.internal.TestInvoker.invokeTestMethods(TestInvoker.java:146)
at org.testng.internal.TestMethodWorker.invokeTestMethods(TestMethodWorker.java:146)
at org.testng.internal.TestMethodWorker.run(TestMethodWorker.java:128)
at java.base/java.util.ArrayList.forEach(ArrayList.java:1511)
at org.testng.TestRunner.privateRun(TestRunner.java:794)
at org.testng.TestRunner.run(TestRunner.java:596)
at org.testng.SuiteRunner.runTest(SuiteRunner.java:377)
at org.testng.SuiteRunner.runSequentially(SuiteRunner.java:371)
at org.testng.SuiteRunner.privateRun(SuiteRunner.java:332)
at org.testng.SuiteRunner.run(SuiteRunner.java:276)
at org.testng.SuiteRunnerWorker.runSuite(SuiteRunnerWorker.java:53)
at org.testng.SuiteRunnerWorker.run(SuiteRunnerWorker.java:96)
at org.testng.TestNG.runSuitesSequentially(TestNG.java:1212)
at org.testng.TestNG.runSuitesLocally(TestNG.java:1134)
at org.testng.TestNG.runSuites(TestNG.java:1063)
at org.testng.TestNG.run(TestNG.java:1031)
at org.testng.remote.AbstractRemoteTestNG.run(AbstractRemoteTestNG.java:115)
at org.testng.remote.RemoteTestNG.initAndRun(RemoteTestNG.java:251)
at org.testng.remote.RemoteTestNG.main(RemoteTestNG.java:77)
]]>
            </full-stacktrace>
          </exception> <!-- java.lang.AssertionError -->
          <reporter-output>
          </reporter-output>
        </test-method> <!-- DDT_LoginTestTC001 -->
        <test-method signature="DDT_LoginTestTC001(java.lang.String,java.lang.String)[pri:0, instance:testcases.TC001_DDTLoginTest@3ee37e5a]" started-at="2023-05-31T15:37:50 IST" name="DDT_LoginTestTC001" data-provider="DDTExcel" finished-at="2023-05-31T15:37:54 IST" duration-ms="4666" status="FAIL">
          <params>
            <param index="0">
              <value>
                <![CDATA[Baba]]>
              </value>
            </param>
            <param index="1">
              <value>
                <![CDATA[Ammi]]>
              </value>
            </param>
          </params>
          <exception class="java.lang.AssertionError">
            <full-stacktrace>
              <![CDATA[java.lang.AssertionError
at org.junit.Assert.fail(Assert.java:86)
at org.junit.Assert.assertTrue(Assert.java:41)
at org.junit.Assert.assertTrue(Assert.java:52)
at testcases.TC001_DDTLoginTest.DDT_LoginTestTC001(TC001_DDTLoginTest.java:28)
at java.base/jdk.internal.reflect.NativeMethodAccessorImpl.invoke0(Native Method)
at java.base/jdk.internal.reflect.NativeMethodAccessorImpl.invoke(NativeMethodAccessorImpl.java:64)
at java.base/jdk.internal.reflect.DelegatingMethodAccessorImpl.invoke(DelegatingMethodAccessorImpl.java:43)
at java.base/java.lang.reflect.Method.invoke(Method.java:564)
at org.testng.internal.MethodInvocationHelper.invokeMethod(MethodInvocationHelper.java:133)
at org.testng.internal.TestInvoker.invokeMethod(TestInvoker.java:598)
at org.testng.internal.TestInvoker.invokeTestMethod(TestInvoker.java:173)
at org.testng.internal.MethodRunner.runInSequence(MethodRunner.java:46)
at org.testng.internal.TestInvoker$MethodInvocationAgent.invoke(TestInvoker.java:824)
at org.testng.internal.TestInvoker.invokeTestMethods(TestInvoker.java:146)
at org.testng.internal.TestMethodWorker.invokeTestMethods(TestMethodWorker.java:146)
at org.testng.internal.TestMethodWorker.run(TestMethodWorker.java:128)
at java.base/java.util.ArrayList.forEach(ArrayList.java:1511)
at org.testng.TestRunner.privateRun(TestRunner.java:794)
at org.testng.TestRunner.run(TestRunner.java:596)
at org.testng.SuiteRunner.runTest(SuiteRunner.java:377)
at org.testng.SuiteRunner.runSequentially(SuiteRunner.java:371)
at org.testng.SuiteRunner.privateRun(SuiteRunner.java:332)
at org.testng.SuiteRunner.run(SuiteRunner.java:276)
at org.testng.SuiteRunnerWorker.runSuite(SuiteRunnerWorker.java:53)
at org.testng.SuiteRunnerWorker.run(SuiteRunnerWorker.java:96)
at org.testng.TestNG.runSuitesSequentially(TestNG.java:1212)
at org.testng.TestNG.runSuitesLocally(TestNG.java:1134)
at org.testng.TestNG.runSuites(TestNG.java:1063)
at org.testng.TestNG.run(TestNG.java:1031)
at org.testng.remote.AbstractRemoteTestNG.run(AbstractRemoteTestNG.java:115)
at org.testng.remote.RemoteTestNG.initAndRun(RemoteTestNG.java:251)
at org.testng.remote.RemoteTestNG.main(RemoteTestNG.java:77)
]]>
            </full-stacktrace>
          </exception> <!-- java.lang.AssertionError -->
          <reporter-output>
          </reporter-output>
        </test-method> <!-- DDT_LoginTestTC001 -->
        <test-method signature="DDT_LoginTestTC001(java.lang.String,java.lang.String)[pri:0, instance:testcases.TC001_DDTLoginTest@3ee37e5a]" started-at="2023-05-31T15:37:54 IST" name="DDT_LoginTestTC001" data-provider="DDTExcel" finished-at="2023-05-31T15:37:59 IST" duration-ms="4367" status="FAIL">
          <params>
            <param index="0">
              <value>
                <![CDATA[Ayesha]]>
              </value>
            </param>
            <param index="1">
              <value>
                <![CDATA[Nuha]]>
              </value>
            </param>
          </params>
          <exception class="java.lang.AssertionError">
            <full-stacktrace>
              <![CDATA[java.lang.AssertionError
at org.junit.Assert.fail(Assert.java:86)
at org.junit.Assert.assertTrue(Assert.java:41)
at org.junit.Assert.assertTrue(Assert.java:52)
at testcases.TC001_DDTLoginTest.DDT_LoginTestTC001(TC001_DDTLoginTest.java:28)
at java.base/jdk.internal.reflect.NativeMethodAccessorImpl.invoke0(Native Method)
at java.base/jdk.internal.reflect.NativeMethodAccessorImpl.invoke(NativeMethodAccessorImpl.java:64)
at java.base/jdk.internal.reflect.DelegatingMethodAccessorImpl.invoke(DelegatingMethodAccessorImpl.java:43)
at java.base/java.lang.reflect.Method.invoke(Method.java:564)
at org.testng.internal.MethodInvocationHelper.invokeMethod(MethodInvocationHelper.java:133)
at org.testng.internal.TestInvoker.invokeMethod(TestInvoker.java:598)
at org.testng.internal.TestInvoker.invokeTestMethod(TestInvoker.java:173)
at org.testng.internal.MethodRunner.runInSequence(MethodRunner.java:46)
at org.testng.internal.TestInvoker$MethodInvocationAgent.invoke(TestInvoker.java:824)
at org.testng.internal.TestInvoker.invokeTestMethods(TestInvoker.java:146)
at org.testng.internal.TestMethodWorker.invokeTestMethods(TestMethodWorker.java:146)
at org.testng.internal.TestMethodWorker.run(TestMethodWorker.java:128)
at java.base/java.util.ArrayList.forEach(ArrayList.java:1511)
at org.testng.TestRunner.privateRun(TestRunner.java:794)
at org.testng.TestRunner.run(TestRunner.java:596)
at org.testng.SuiteRunner.runTest(SuiteRunner.java:377)
at org.testng.SuiteRunner.runSequentially(SuiteRunner.java:371)
at org.testng.SuiteRunner.privateRun(SuiteRunner.java:332)
at org.testng.SuiteRunner.run(SuiteRunner.java:276)
at org.testng.SuiteRunnerWorker.runSuite(SuiteRunnerWorker.java:53)
at org.testng.SuiteRunnerWorker.run(SuiteRunnerWorker.java:96)
at org.testng.TestNG.runSuitesSequentially(TestNG.java:1212)
at org.testng.TestNG.runSuitesLocally(TestNG.java:1134)
at org.testng.TestNG.runSuites(TestNG.java:1063)
at org.testng.TestNG.run(TestNG.java:1031)
at org.testng.remote.AbstractRemoteTestNG.run(AbstractRemoteTestNG.java:115)
at org.testng.remote.RemoteTestNG.initAndRun(RemoteTestNG.java:251)
at org.testng.remote.RemoteTestNG.main(RemoteTestNG.java:77)
]]>
            </full-stacktrace>
          </exception> <!-- java.lang.AssertionError -->
          <reporter-output>
          </reporter-output>
        </test-method> <!-- DDT_LoginTestTC001 -->
        <test-method signature="DDT_LoginTestTC001(java.lang.String,java.lang.String)[pri:0, instance:testcases.TC001_DDTLoginTest@3ee37e5a]" started-at="2023-05-31T15:37:59 IST" name="DDT_LoginTestTC001" data-provider="DDTExcel" finished-at="2023-05-31T15:38:03 IST" duration-ms="4440" status="FAIL">
          <params>
            <param index="0">
              <value>
                <![CDATA[Atiya]]>
              </value>
            </param>
            <param index="1">
              <value>
                <![CDATA[hannan]]>
              </value>
            </param>
          </params>
          <exception class="java.lang.AssertionError">
            <full-stacktrace>
              <![CDATA[java.lang.AssertionError
at org.junit.Assert.fail(Assert.java:86)
at org.junit.Assert.assertTrue(Assert.java:41)
at org.junit.Assert.assertTrue(Assert.java:52)
at testcases.TC001_DDTLoginTest.DDT_LoginTestTC001(TC001_DDTLoginTest.java:28)
at java.base/jdk.internal.reflect.NativeMethodAccessorImpl.invoke0(Native Method)
at java.base/jdk.internal.reflect.NativeMethodAccessorImpl.invoke(NativeMethodAccessorImpl.java:64)
at java.base/jdk.internal.reflect.DelegatingMethodAccessorImpl.invoke(DelegatingMethodAccessorImpl.java:43)
at java.base/java.lang.reflect.Method.invoke(Method.java:564)
at org.testng.internal.MethodInvocationHelper.invokeMethod(MethodInvocationHelper.java:133)
at org.testng.internal.TestInvoker.invokeMethod(TestInvoker.java:598)
at org.testng.internal.TestInvoker.invokeTestMethod(TestInvoker.java:173)
at org.testng.internal.MethodRunner.runInSequence(MethodRunner.java:46)
at org.testng.internal.TestInvoker$MethodInvocationAgent.invoke(TestInvoker.java:824)
at org.testng.internal.TestInvoker.invokeTestMethods(TestInvoker.java:146)
at org.testng.internal.TestMethodWorker.invokeTestMethods(TestMethodWorker.java:146)
at org.testng.internal.TestMethodWorker.run(TestMethodWorker.java:128)
at java.base/java.util.ArrayList.forEach(ArrayList.java:1511)
at org.testng.TestRunner.privateRun(TestRunner.java:794)
at org.testng.TestRunner.run(TestRunner.java:596)
at org.testng.SuiteRunner.runTest(SuiteRunner.java:377)
at org.testng.SuiteRunner.runSequentially(SuiteRunner.java:371)
at org.testng.SuiteRunner.privateRun(SuiteRunner.java:332)
at org.testng.SuiteRunner.run(SuiteRunner.java:276)
at org.testng.SuiteRunnerWorker.runSuite(SuiteRunnerWorker.java:53)
at org.testng.SuiteRunnerWorker.run(SuiteRunnerWorker.java:96)
at org.testng.TestNG.runSuitesSequentially(TestNG.java:1212)
at org.testng.TestNG.runSuitesLocally(TestNG.java:1134)
at org.testng.TestNG.runSuites(TestNG.java:1063)
at org.testng.TestNG.run(TestNG.java:1031)
at org.testng.remote.AbstractRemoteTestNG.run(AbstractRemoteTestNG.java:115)
at org.testng.remote.RemoteTestNG.initAndRun(RemoteTestNG.java:251)
at org.testng.remote.RemoteTestNG.main(RemoteTestNG.java:77)
]]>
            </full-stacktrace>
          </exception> <!-- java.lang.AssertionError -->
          <reporter-output>
          </reporter-output>
        </test-method> <!-- DDT_LoginTestTC001 -->
        <test-method signature="DDT_LoginTestTC001(java.lang.String,java.lang.String)[pri:0, instance:testcases.TC001_DDTLoginTest@3ee37e5a]" started-at="2023-05-31T15:38:03 IST" name="DDT_LoginTestTC001" data-provider="DDTExcel" finished-at="2023-05-31T15:38:08 IST" duration-ms="4370" status="FAIL">
          <params>
            <param index="0">
              <value>
                <![CDATA[Hakeem]]>
              </value>
            </param>
            <param index="1">
              <value>
                <![CDATA[Mehar]]>
              </value>
            </param>
          </params>
          <exception class="java.lang.AssertionError">
            <full-stacktrace>
              <![CDATA[java.lang.AssertionError
at org.junit.Assert.fail(Assert.java:86)
at org.junit.Assert.assertTrue(Assert.java:41)
at org.junit.Assert.assertTrue(Assert.java:52)
at testcases.TC001_DDTLoginTest.DDT_LoginTestTC001(TC001_DDTLoginTest.java:28)
at java.base/jdk.internal.reflect.NativeMethodAccessorImpl.invoke0(Native Method)
at java.base/jdk.internal.reflect.NativeMethodAccessorImpl.invoke(NativeMethodAccessorImpl.java:64)
at java.base/jdk.internal.reflect.DelegatingMethodAccessorImpl.invoke(DelegatingMethodAccessorImpl.java:43)
at java.base/java.lang.reflect.Method.invoke(Method.java:564)
at org.testng.internal.MethodInvocationHelper.invokeMethod(MethodInvocationHelper.java:133)
at org.testng.internal.TestInvoker.invokeMethod(TestInvoker.java:598)
at org.testng.internal.TestInvoker.invokeTestMethod(TestInvoker.java:173)
at org.testng.internal.MethodRunner.runInSequence(MethodRunner.java:46)
at org.testng.internal.TestInvoker$MethodInvocationAgent.invoke(TestInvoker.java:824)
at org.testng.internal.TestInvoker.invokeTestMethods(TestInvoker.java:146)
at org.testng.internal.TestMethodWorker.invokeTestMethods(TestMethodWorker.java:146)
at org.testng.internal.TestMethodWorker.run(TestMethodWorker.java:128)
at java.base/java.util.ArrayList.forEach(ArrayList.java:1511)
at org.testng.TestRunner.privateRun(TestRunner.java:794)
at org.testng.TestRunner.run(TestRunner.java:596)
at org.testng.SuiteRunner.runTest(SuiteRunner.java:377)
at org.testng.SuiteRunner.runSequentially(SuiteRunner.java:371)
at org.testng.SuiteRunner.privateRun(SuiteRunner.java:332)
at org.testng.SuiteRunner.run(SuiteRunner.java:276)
at org.testng.SuiteRunnerWorker.runSuite(SuiteRunnerWorker.java:53)
at org.testng.SuiteRunnerWorker.run(SuiteRunnerWorker.java:96)
at org.testng.TestNG.runSuitesSequentially(TestNG.java:1212)
at org.testng.TestNG.runSuitesLocally(TestNG.java:1134)
at org.testng.TestNG.runSuites(TestNG.java:1063)
at org.testng.TestNG.run(TestNG.java:1031)
at org.testng.remote.AbstractRemoteTestNG.run(AbstractRemoteTestNG.java:115)
at org.testng.remote.RemoteTestNG.initAndRun(RemoteTestNG.java:251)
at org.testng.remote.RemoteTestNG.main(RemoteTestNG.java:77)
]]>
            </full-stacktrace>
          </exception> <!-- java.lang.AssertionError -->
          <reporter-output>
          </reporter-output>
        </test-method> <!-- DDT_LoginTestTC001 -->
        <test-method is-config="true" signature="closeBrow()[pri:0, instance:testcases.TC001_DDTLoginTest@3ee37e5a]" started-at="2023-05-31T15:38:08 IST" name="closeBrow" finished-at="2023-05-31T15:38:12 IST" duration-ms="3853" status="PASS">
          <reporter-output>
          </reporter-output>
        </test-method> <!-- closeBrow -->
      </class> <!-- testcases.TC001_DDTLoginTest -->
    </test> <!-- Default test -->
  </suite> <!-- Default suite -->
</testng-results>
